2024-03-24 13:57:48,090 INFO    StreamThr :15096 [internal.py:wandb_internal():86] W&B internal server running at pid: 15096, started at: 2024-03-24 13:57:48.088908
2024-03-24 13:57:48,092 DEBUG   HandlerThread:15096 [handler.py:handle_request():146] handle_request: status
2024-03-24 13:57:48,118 INFO    WriterThread:15096 [datastore.py:open_for_write():87] open: C:\Users\raul\Universidad Pontificia Comillas\Javier Álvarez Martínez - MachineLoooorning\wandb\run-20240324_135748-5gb6399l\run-5gb6399l.wandb
2024-03-24 13:57:48,119 DEBUG   SenderThread:15096 [sender.py:send():378] send: header
2024-03-24 13:57:48,122 DEBUG   SenderThread:15096 [sender.py:send():378] send: run
2024-03-24 13:57:49,700 ERROR   SenderThread:15096 [internal_api.py:execute():373] 404 response executing GraphQL.
2024-03-24 13:57:49,700 ERROR   SenderThread:15096 [internal_api.py:execute():374] {"errors":[{"message":"entity tu_usuario not found during upsertBucket","path":["upsertBucket"]}],"data":{"upsertBucket":null}}
2024-03-24 13:57:49,710 ERROR   SenderThread:15096 [sender.py:send_run():950] It appears that you do not have permission to access the requested resource. Please reach out to the project owner to grant you access. If you have the correct permissions, verify that there are no issues with your networking setup.(Error 404: Not Found)
Traceback (most recent call last):
  File "C:\Users\raul\.conda\envs\noestructurados\Lib\site-packages\wandb\sdk\lib\retry.py", line 131, in __call__
    result = self._call_fn(*args, **kwargs)
             ^^^^^^^^^^^^^^^^^^^^^^^^^^^^^^
  File "C:\Users\raul\.conda\envs\noestructurados\Lib\site-packages\wandb\sdk\internal\internal_api.py", line 369, in execute
    return self.client.execute(*args, **kwargs)  # type: ignore
           ^^^^^^^^^^^^^^^^^^^^^^^^^^^^^^^^^^^^
  File "C:\Users\raul\.conda\envs\noestructurados\Lib\site-packages\wandb\vendor\gql-0.2.0\wandb_gql\client.py", line 52, in execute
    result = self._get_result(document, *args, **kwargs)
             ^^^^^^^^^^^^^^^^^^^^^^^^^^^^^^^^^^^^^^^^^^^
  File "C:\Users\raul\.conda\envs\noestructurados\Lib\site-packages\wandb\vendor\gql-0.2.0\wandb_gql\client.py", line 60, in _get_result
    return self.transport.execute(document, *args, **kwargs)
           ^^^^^^^^^^^^^^^^^^^^^^^^^^^^^^^^^^^^^^^^^^^^^^^^^
  File "C:\Users\raul\.conda\envs\noestructurados\Lib\site-packages\wandb\sdk\lib\gql_request.py", line 59, in execute
    request.raise_for_status()
  File "C:\Users\raul\.conda\envs\noestructurados\Lib\site-packages\requests\models.py", line 1021, in raise_for_status
    raise HTTPError(http_error_msg, response=self)
requests.exceptions.HTTPError: 404 Client Error: Not Found for url: https://api.wandb.ai/graphql

During handling of the above exception, another exception occurred:

Traceback (most recent call last):
  File "C:\Users\raul\.conda\envs\noestructurados\Lib\site-packages\wandb\sdk\internal\sender.py", line 948, in send_run
    self._init_run(run, config_value_dict)
  File "C:\Users\raul\.conda\envs\noestructurados\Lib\site-packages\wandb\sdk\internal\sender.py", line 990, in _init_run
    server_run, inserted, server_messages = self._api.upsert_run(
                                            ^^^^^^^^^^^^^^^^^^^^^
  File "C:\Users\raul\.conda\envs\noestructurados\Lib\site-packages\wandb\apis\normalize.py", line 73, in wrapper
    raise err
  File "C:\Users\raul\.conda\envs\noestructurados\Lib\site-packages\wandb\apis\normalize.py", line 41, in wrapper
    return func(*args, **kwargs)
           ^^^^^^^^^^^^^^^^^^^^^
  File "C:\Users\raul\.conda\envs\noestructurados\Lib\site-packages\wandb\sdk\internal\internal_api.py", line 2216, in upsert_run
    response = self.gql(
               ^^^^^^^^^
  File "C:\Users\raul\.conda\envs\noestructurados\Lib\site-packages\wandb\sdk\internal\internal_api.py", line 341, in gql
    ret = self._retry_gql(
          ^^^^^^^^^^^^^^^^
  File "C:\Users\raul\.conda\envs\noestructurados\Lib\site-packages\wandb\sdk\lib\retry.py", line 147, in __call__
    retry_timedelta_triggered = check_retry_fn(e)
                                ^^^^^^^^^^^^^^^^^
  File "C:\Users\raul\.conda\envs\noestructurados\Lib\site-packages\wandb\util.py", line 968, in check_retry_fn
    return fallback_retry_fn(e)
           ^^^^^^^^^^^^^^^^^^^^
  File "C:\Users\raul\.conda\envs\noestructurados\Lib\site-packages\wandb\util.py", line 910, in no_retry_auth
    raise CommError(
wandb.errors.CommError: It appears that you do not have permission to access the requested resource. Please reach out to the project owner to grant you access. If you have the correct permissions, verify that there are no issues with your networking setup.(Error 404: Not Found)
2024-03-24 13:57:51,122 DEBUG   HandlerThread:15096 [handler.py:handle_request():146] handle_request: shutdown
2024-03-24 13:57:51,122 INFO    HandlerThread:15096 [handler.py:finish():869] shutting down handler
2024-03-24 13:57:51,139 INFO    WriterThread:15096 [datastore.py:close():296] close: C:\Users\raul\Universidad Pontificia Comillas\Javier Álvarez Martínez - MachineLoooorning\wandb\run-20240324_135748-5gb6399l\run-5gb6399l.wandb
2024-03-24 13:57:51,752 INFO    SenderThread:15096 [sender.py:finish():1521] shutting down sender
